<?xml version="1.0" encoding="utf-8"?>
<!-- This URDF was automatically created by SolidWorks to URDF Exporter! Originally created by Stephen Brawner (brawner@gmail.com) 
     Commit Version: 1.6.0-4-g7f85cfe  Build Version: 1.6.7995.38578
     For more information, please see http://wiki.ros.org/sw_urdf_exporter -->
<robot
  name="VLAI_humanoid">
  <mujoco>
    <compiler meshdir="../meshes" discardvisual="false" />
  </mujoco>
  <link
    name="base_link">
    <inertial>
      <origin
        xyz="0.001426 -6.1639E-05 0.19623"
        rpy="0 0 0" />
      <mass
        value="21.95398" />
      <inertia
        ixx="0.27034"
        ixy="-3.7467E-06"
        ixz="0.00064786"
        iyy="0.16671"
        iyz="2.7755E-05"
        izz="0.11219" />
    </inertial>
    <visual>
      <origin
        xyz="0 0 0"
        rpy="0 0 0" />
      <geometry>
        <mesh
          filename="../meshes/base_link.STL" />
      </geometry>
      <material
        name="">
        <color
          rgba="0.89804 0.91765 0.92941 1" />
      </material>
    </visual>
    <collision>
      <origin
        xyz="0 0 0"
        rpy="0 0 0" />
      <geometry>
        <mesh
          filename="../meshes/base_link.STL" />
      </geometry>
    </collision>
  </link>
  <link
    name="arm_r1_link1">
    <inertial>
      <origin
        xyz="-0.0057802 -0.0020249 -0.00072745"
        rpy="0 0 0" />
      <mass
        value="0.43322" />
      <inertia
        ixx="0.00012291"
        ixy="-3.0937E-05"
        ixz="-9.4478E-06"
        iyy="0.00011143"
        iyz="-1.3141E-05"
        izz="0.00013652" />
    </inertial>
    <visual>
      <origin
        xyz="0 0 0"
        rpy="0 0 0" />
      <geometry>
        <mesh
          filename="../meshes/ arm_r1_link1.STL" />
      </geometry>
      <material
        name="">
        <color
          rgba="0.89804 0.91765 0.92941 1" />
      </material>
    </visual>
    <collision>
      <origin
        xyz="0 0 0"
        rpy="0 0 0" />
      <geometry>
        <mesh
          filename="../meshes/ arm_r1_link1.STL" />
      </geometry>
    </collision>
  </link>
  <joint
    name="arm_r1_joint1"
    type="fixed">
    <origin
      xyz="0 -0.13063 0.25938"
      rpy="0 0 0" />
    <parent
      link="base_link" />
    <child
      link="arm_r1_link1" />
    <axis
      xyz="0 -1 -0.00051801" />
    <limit
      lower="-3.1"
      upper="3.1"
      effort="7"
      velocity="5" />
  </joint>
  <link
    name="arm_r2_link2">
    <inertial>
      <origin
        xyz="0.107 0.012299 -0.11222"
        rpy="0 0 0" />
      <mass
        value="3.62597" />
      <inertia
        ixx="0.020204"
        ixy="-8.6209E-08"
        ixz="1.0488E-05"
        iyy="0.019093"
        iyz="0.00018377"
        izz="0.0017737" />
    </inertial>
    <visual>
      <origin
        xyz="0 0 0"
        rpy="0 0 0" />
      <geometry>
        <mesh
          filename="../meshes/arm_r2_link2.STL" />
      </geometry>
      <material
        name="">
        <color
          rgba="0.89804 0.91765 0.92941 1" />
      </material>
    </visual>
    <collision>
      <origin
        xyz="0 0 0"
        rpy="0 0 0" />
      <geometry>
        <mesh
          filename="../meshes/arm_r2_link2.STL" />
      </geometry>
    </collision>
  </link>
  <joint
    name="arm_r2_joint2"
    type="fixed">
    <origin
      xyz="-0.01905 -0.047495 -0.0088799"
      rpy="0 0 0" />
    <parent
      link="arm_r1_link1" />
    <child
      link="arm_r2_link2" />
    <axis
      xyz="1 0 0" />
    <limit
      lower="-3.1"
      upper="0"
      effort="7"
      velocity="5" />
  </joint>
  <link
    name="arm_r3_link3 ">
    <inertial>
      <origin
        xyz="0.076321 -0.069713 -0.008762"
        rpy="0 0 0" />
      <mass
        value="2.5778" />
      <inertia
        ixx="0.0011148"
        ixy="-9.7377E-06"
        ixz="0.0013559"
        iyy="0.0096138"
        iyz="2.3517E-06"
        izz="0.0090859" />
    </inertial>
    <visual>
      <origin
        xyz="0 0 0"
        rpy="0 0 0" />
      <geometry>
        <mesh
          filename="../meshes/ arm_r3_link3 .STL" />
      </geometry>
      <material
        name="">
        <color
          rgba="0.89804 0.91765 0.92941 1" />
      </material>
    </visual>
    <collision>
      <origin
        xyz="0 0 0"
        rpy="0 0 0" />
      <geometry>
        <mesh
          filename="../meshes/ arm_r3_link3 .STL" />
      </geometry>
    </collision>
  </link>
  <joint
    name="arm_r3_joint3 "
    type="fixed">
    <origin
      xyz="0.0229 0.023411 -0.23505"
      rpy="0 0 0" />
    <parent
      link="arm_r2_link2" />
    <child
      link="arm_r3_link3 " />
    <axis
      xyz="0 -1 -0.00050756" />
    <limit
      lower="-2.6"
      upper="0.52"
      effort="7"
      velocity="5" />
  </joint>
  <link
    name="arm_L1_link4">
    <inertial>
      <origin
        xyz="-0.0057636 0.0020257 -0.00075428"
        rpy="0 0 0" />
      <mass
        value="0.43322" />
      <inertia
        ixx="0.0001231"
        ixy="3.0937E-05"
        ixz="-9.5229E-06"
        iyy="0.0001114"
        iyz="1.3132E-05"
        izz="0.00013636" />
    </inertial>
    <visual>
      <origin
        xyz="0 0 0"
        rpy="0 0 0" />
      <geometry>
        <mesh
          filename="../meshes/arm_L1_link4.STL" />
      </geometry>
      <material
        name="">
        <color
          rgba="0.89804 0.91765 0.92941 1" />
      </material>
    </visual>
    <collision>
      <origin
        xyz="0 0 0"
        rpy="0 0 0" />
      <geometry>
        <mesh
          filename="../meshes/arm_L1_link4.STL" />
      </geometry>
    </collision>
  </link>
  <joint
    name="arm_L1_joint4  "
    type="fixed">
    <origin
      xyz="0 0.13037 0.25952"
      rpy="0 0 0" />
    <parent
      link="base_link" />
    <child
      link="arm_L1_link4" />
    <axis
      xyz="0 -1 -0.00051801" />
    <limit
      lower="-3.1"
      upper="3.1"
      effort="7"
      velocity="5" />
  </joint>
  <link
    name="arm_L2_link5">
    <inertial>
      <origin
        xyz="0.11002 -0.014202 -0.11149"
        rpy="0 0 0" />
      <mass
        value="3.08959" />
      <inertia
        ixx="0.017088"
        ixy="-9.0755E-08"
        ixz="-6.5469E-07"
        iyy="0.016178"
        iyz="-0.00011848"
        izz="0.0014708" />
    </inertial>
    <visual>
      <origin
        xyz="0 0 0"
        rpy="0 0 0" />
      <geometry>
        <mesh
          filename="../meshes/arm_L2_link5.STL" />
      </geometry>
      <material
        name="">
        <color
          rgba="0.89804 0.91765 0.92941 1" />
      </material>
    </visual>
    <collision>
      <origin
        xyz="0 0 0"
        rpy="0 0 0" />
      <geometry>
        <mesh
          filename="../meshes/arm_L2_link5.STL" />
      </geometry>
    </collision>
  </link>
  <joint
    name="arm_L2_joint5"
    type="fixed">
    <origin
      xyz="-0.01905 0.047504 -0.0088316"
      rpy="0 0 0" />
    <parent
      link="arm_L1_link4" />
    <child
      link="arm_L2_link5" />
    <axis
      xyz="1 0 0" />
    <limit
      lower="0"
      upper="3.1"
      effort="7"
      velocity="5" />
  </joint>
  <link
    name="arm_L3_link6">
    <inertial>
      <origin
        xyz="0.081839 0.055803 -0.010384"
        rpy="0 0 0" />
      <mass
        value="3.09128" />
      <inertia
        ixx="0.0013632"
        ixy="-6.2573E-05"
        ixz="0.0016992"
        iyy="0.011903"
        iyz="1.1057E-05"
        izz="0.011205" />
    </inertial>
    <visual>
      <origin
        xyz="0 0 0"
        rpy="0 0 0" />
      <geometry>
        <mesh
          filename="../meshes/arm_L3_link6.STL" />
      </geometry>
      <material
        name="">
        <color
          rgba="0.89804 0.91765 0.92941 1" />
      </material>
    </visual>
    <collision>
      <origin
        xyz="0 0 0"
        rpy="0 0 0" />
      <geometry>
        <mesh
          filename="../meshes/arm_L3_link6.STL" />
      </geometry>
    </collision>
  </link>
  <joint
    name="arm_L3_joint6"
    type="fixed">
    <origin
      xyz="0.023 -0.023172 -0.23508"
      rpy="0 0 0" />
    <parent
      link="arm_L2_link5" />
    <child
      link="arm_L3_link6" />
    <axis
      xyz="0 1 0.00050756" />
    <limit
      lower="-0.52"
      upper="2.6"
      effort="7"
      velocity="5" />
  </joint>
  <link
    name="leg_R1_link7">
    <inertial>
      <origin
        xyz="-0.047978 -0.00060444 -0.034706"
        rpy="0 0 0" />
      <mass
        value="1.6872" />
      <inertia
        ixx="0.0013034"
        ixy="1.2226E-06"
        ixz="-0.00018794"
        iyy="0.0011617"
        iyz="-2.2086E-06"
        izz="0.0011385" />
    </inertial>
    <visual>
      <origin
        xyz="0 0 0"
        rpy="0 0 0" />
      <geometry>
        <mesh
          filename="../meshes/ leg_R1_link7.STL" />
      </geometry>
      <material
        name="">
        <color
          rgba="0.89804 0.91765 0.92941 1" />
      </material>
    </visual>
    <collision>
      <origin
        xyz="0 0 0"
        rpy="0 0 0" />
      <geometry>
        <mesh
          filename="../meshes/ leg_R1_link7.STL" />
      </geometry>
    </collision>
  </link>
  <joint
    name="leg_R1_joint7"
    type="revolute">
    <origin
      xyz="0 -0.080999 -0.0025411"
      rpy="0 0 0" />
    <parent
      link="base_link" />
    <child
      link="leg_R1_link7" />
    <axis
      xyz="0 -0.00051801 1" />
    <limit
      lower="-0.28"
      upper="0.46"
      effort="36"
      velocity="5" />
  </joint>
  <link
    name="leg_R2_link8">
    <inertial>
      <origin
        xyz="0.073875 -0.042566 0.00021144"
        rpy="0 0 0" />
      <mass
        value="1.81572" />
      <inertia
        ixx="0.00095814"
        ixy="5.8645E-05"
        ixz="1.8884E-06"
        iyy="0.0019411"
        iyz="-6.3365E-06"
        izz="0.0011543" />
    </inertial>
    <visual>
      <origin
        xyz="0 0 0"
        rpy="0 0 0" />
      <geometry>
        <mesh
          filename="../meshes/leg_R2_link8.STL" />
      </geometry>
      <material
        name="">
        <color
          rgba="0.89804 0.91765 0.92941 1" />
      </material>
    </visual>
    <collision>
      <origin
        xyz="0 0 0"
        rpy="0 0 0" />
      <geometry>
        <mesh
          filename="../meshes/leg_R2_link8.STL" />
      </geometry>
    </collision>
  </link>
  <joint
    name="leg_R2_joint8"
    type="revolute">
    <origin
      xyz="-0.079245 -0.00081545 -0.087803"
      rpy="0 0 0" />
    <parent
      link="leg_R1_link7" />
    <child
      link="leg_R2_link8" />
    <axis
      xyz="-0.99994 -0.010852 0" />
    <limit
      lower="-0.3"
      upper="0.2"
      effort="120"
      velocity="5" />
  </joint>
  <link
    name="leg_R3_link9">
    <inertial>
      <origin
        xyz="0.024319 0.0068055 -0.086184"
        rpy="0 0 0" />
      <mass
        value="3.86581" />
      <inertia
        ixx="0.014393"
        ixy="9.6428E-05"
        ixz="0.004418"
        iyy="0.017912"
        iyz="-0.00029627"
        izz="0.0038321" />
    </inertial>
    <visual>
      <origin
        xyz="0 0 0"
        rpy="0 0 0" />
      <geometry>
        <mesh
          filename="../meshes/leg_R3_link9.STL" />
      </geometry>
      <material
        name="">
        <color
          rgba="0.79216 0.81961 0.93333 1" />
      </material>
    </visual>
    <collision>
      <origin
        xyz="0 0 0"
        rpy="0 0 0" />
      <geometry>
        <mesh
          filename="../meshes/leg_R3_link9.STL" />
      </geometry>
    </collision>
  </link>
  <joint
    name="leg_R3_joint9"
    type="revolute">
    <origin
      xyz="0.090654 -0.029017 0.00022094"
      rpy="0 0 0" />
    <parent
      link="leg_R2_link8" />
    <child
      link="leg_R3_link9" />
    <axis
      xyz="0.010852 -0.99991 0.007347" />
    <limit
      lower="-0.3"
      upper="0.2"
      effort="120"
      velocity="5" />
  </joint>
  <link
    name="leg_R4_link10">
    <inertial>
      <origin
        xyz="-0.033346 -0.0012327 -0.11954"
        rpy="0 0 0" />
      <mass
        value="1.16434" />
      <inertia
        ixx="0.0033972"
        ixy="-8.0392E-06"
        ixz="-0.00088362"
        iyy="0.0035446"
        iyz="-3.1253E-05"
        izz="0.00058322" />
    </inertial>
    <visual>
      <origin
        xyz="0 0 0"
        rpy="0 0 0" />
      <geometry>
        <mesh
          filename="../meshes/leg_R4_link10.STL" />
      </geometry>
      <material
        name="">
        <color
          rgba="0.89804 0.91765 0.92941 1" />
      </material>
    </visual>
    <collision>
      <origin
        xyz="0 0 0"
        rpy="0 0 0" />
      <geometry>
        <mesh
          filename="../meshes/leg_R4_link10.STL" />
      </geometry>
    </collision>
  </link>
  <joint
    name="leg_R4_joint10"
    type="revolute">
    <origin
      xyz="0.064379 0.023415 -0.24307"
      rpy="0 0 0" />
    <parent
      link="leg_R3_link9" />
    <child
      link="leg_R4_link10" />
    <axis
      xyz="-0.010852 0.99991 -0.007347" />
    <limit
      lower="0"
      upper="1.4"
      effort="7"
      velocity="5" />
  </joint>
  <link
    name="leg_R5_link11">
    <inertial>
      <origin
        xyz="0.03541 0.00029651 -0.02836"
        rpy="0 0 0" />
      <mass
        value="0.37577" />
      <inertia
        ixx="0.00010276"
        ixy="-7.9812E-06"
        ixz="-3.5515E-06"
        iyy="0.0008384"
        iyz="-4.0147E-08"
        izz="0.00092829" />
    </inertial>
    <visual>
      <origin
        xyz="0 0 0"
        rpy="0 0 0" />
      <geometry>
        <mesh
          filename="../meshes/ leg_R5_link11.STL" />
      </geometry>
      <material
        name="">
        <color
          rgba="0.89804 0.91765 0.92941 1" />
      </material>
    </visual>
    <collision>
      <origin
        xyz="0 0 0"
        rpy="0 0 0" />
      <geometry>
        <mesh
          filename="../meshes/ leg_R5_link11.STL" />
      </geometry>
    </collision>
  </link>
  <joint
    name="leg_R5_joint11"
    type="revolute">
    <origin
      xyz="-0.081907 -0.0028183 -0.26259"
      rpy="0 0 0" />
    <parent
      link="leg_R4_link10" />
    <child
      link="leg_R5_link11" />
    <axis
      xyz="0.010852 -0.99991 0.007347" />
    <limit
      lower="-0.35"
      upper="0.43"
      effort="7"
      velocity="5" />
  </joint>
  <link
    name="leg_L1_link 12">
    <inertial>
      <origin
        xyz="-0.048018 -0.00014833 -0.04116"
        rpy="0 0 0" />
      <mass
        value="1.6872" />
      <inertia
        ixx="0.0013041"
        ixy="2.5971E-07"
        ixz="-0.000188"
        iyy="0.0011604"
        iyz="-9.9919E-07"
        izz="0.0011391" />
    </inertial>
    <visual>
      <origin
        xyz="0 0 0"
        rpy="0 0 0" />
      <geometry>
        <mesh
          filename="../meshes/leg_L1_link 12.STL" />
      </geometry>
      <material
        name="">
        <color
          rgba="0.89804 0.91765 0.92941 1" />
      </material>
    </visual>
    <collision>
      <origin
        xyz="0 0 0"
        rpy="0 0 0" />
      <geometry>
        <mesh
          filename="../meshes/leg_L1_link 12.STL" />
      </geometry>
    </collision>
  </link>
  <joint
    name="leg_L1_joint12"
    type="revolute">
    <origin
      xyz="0 0.080998 0.0040411"
      rpy="0 0 0" />
    <parent
      link="base_link" />
    <child
      link="leg_L1_link 12" />
    <axis
      xyz="0 0.00050756 -1" />
    <limit
      lower="-0.46"
      upper="0.28"
      effort="36"
      velocity="5" />
  </joint>
  <link
    name="leg_L2_link 13">
    <inertial>
      <origin
        xyz="0.073209 0.043621 0.00041346"
        rpy="0 0 0" />
      <mass
        value="1.81572" />
      <inertia
        ixx="0.00096235"
        ixy="-7.2448E-05"
        ixz="-6.7852E-07"
        iyy="0.0019392"
        iyz="7.3633E-06"
        izz="0.0011519" />
    </inertial>
    <visual>
      <origin
        xyz="0 0 0"
        rpy="0 0 0" />
      <geometry>
        <mesh
          filename="../meshes/leg_L2_link 13.STL" />
      </geometry>
      <material
        name="">
        <color
          rgba="0.89804 0.91765 0.92941 1" />
      </material>
    </visual>
    <collision>
      <origin
        xyz="0 0 0"
        rpy="0 0 0" />
      <geometry>
        <mesh
          filename="../meshes/leg_L2_link 13.STL" />
      </geometry>
    </collision>
  </link>
  <joint
    name="leg_L2_joint13"
    type="revolute">
    <origin
      xyz="-0.07925 -0.00023068 -0.094303"
      rpy="0 0 0" />
    <parent
      link="leg_L1_link 12" />
    <child
      link="leg_L2_link 13" />
    <axis
      xyz="-0.99999 -0.0035147 0" />
    <limit
      lower="-0.2"
      upper="0.3"
      effort="120"
      velocity="5" />
  </joint>
  <link
    name="leg_L3_link 14">
    <inertial>
      <origin
        xyz="0.026087 -0.030326 -0.090996"
        rpy="0 0 0" />
      <mass
        value="4.30102" />
      <inertia
        ixx="0.016999"
        ixy="-5.3693E-05"
        ixz="0.0052509"
        iyy="0.021076"
        iyz="0.00016202"
        izz="0.0044374" />
    </inertial>
    <visual>
      <origin
        xyz="0 0 0"
        rpy="0 0 0" />
      <geometry>
        <mesh
          filename="../meshes/leg_L3_link 14.STL" />
      </geometry>
      <material
        name="">
        <color
          rgba="0.89804 0.91765 0.92941 1" />
      </material>
    </visual>
    <collision>
      <origin
        xyz="0 0 0"
        rpy="0 0 0" />
      <geometry>
        <mesh
          filename="../meshes/leg_L3_link 14.STL" />
      </geometry>
    </collision>
  </link>
  <joint
    name="leg_L3_joint14"
    type="revolute">
    <origin
      xyz="0.090228 0.030316 0.00028276"
      rpy="0 0 0" />
    <parent
      link="leg_L2_link 13" />
    <child
      link="leg_L3_link 14" />
    <axis
      xyz="-0.0035146 0.99995 0.0094213" />
    <limit
      lower="-1.5"
      upper="0.65"
      effort="120"
      velocity="5" />
  </joint>
  <link
    name="leg_L4_link15">
    <inertial>
      <origin
        xyz="-0.032966 0.0010612 -0.11969"
        rpy="0 0 0" />
      <mass
        value="1.16413" />
      <inertia
        ixx="0.0034029"
        ixy="7.7836E-06"
        ixz="-0.00087457"
        iyy="0.0035446"
        iyz="2.4612E-05"
        izz="0.00057757" />
    </inertial>
    <visual>
      <origin
        xyz="0 0 0"
        rpy="0 0 0" />
      <geometry>
        <mesh
          filename="../meshes/leg_L4_link15.STL" />
      </geometry>
      <material
        name="">
        <color
          rgba="0.64706 0.61961 0.58824 1" />
      </material>
    </visual>
    <collision>
      <origin
        xyz="0 0 0"
        rpy="0 0 0" />
      <geometry>
        <mesh
          filename="../meshes/leg_L4_link15.STL" />
      </geometry>
    </collision>
  </link>
  <joint
    name="leg_L4_joint15"
    type="revolute">
    <origin
      xyz="0.064685 -0.021983 -0.24313"
      rpy="0 0 0" />
    <parent
      link="leg_L3_link 14" />
    <child
      link="leg_L4_link15" />
    <axis
      xyz="-0.0035146 0.99995 0.0094213" />
    <limit
      lower="0"
      upper="1.4"
      effort="7"
      velocity="5" />
  </joint>
  <link
    name="leg_L5_link16">
    <inertial>
      <origin
        xyz="0.03541 0.00023671 -0.02836"
        rpy="0 0 0" />
      <mass
        value="0.37577" />
      <inertia
        ixx="0.00010269"
        ixy="-2.5829E-06"
        ixz="-3.5517E-06"
        iyy="0.00083848"
        iyz="-1.1578E-08"
        izz="0.00092829" />
    </inertial>
    <visual>
      <origin
        xyz="0 0 0"
        rpy="0 0 0" />
      <geometry>
        <mesh
          filename="../meshes/leg_L5_link16.STL" />
      </geometry>
      <material
        name="">
        <color
          rgba="0.89804 0.91765 0.92941 1" />
      </material>
    </visual>
    <collision>
      <origin
        xyz="0 0 0"
        rpy="0 0 0" />
      <geometry>
        <mesh
          filename="../meshes/leg_L5_link16.STL" />
      </geometry>
    </collision>
  </link>
  <joint
    name="leg_L5_joint16"
    type="revolute">
    <origin
      xyz="-0.081063 0.0021916 -0.26285"
      rpy="0 0 0" />
    <parent
      link="leg_L4_link15" />
    <child
      link="leg_L5_link16" />
    <axis
      xyz="0.0035146 -0.99995 -0.0094213" />
    <limit
      lower="-0.35"
      upper="0.43"
      effort="7"
      velocity="5" />
  </joint>
</robot>